<?xml version="1.0"?>

<!-- XML namespaces -->
<robot xmlns:sensor="http://playerstage.sourceforge.net/gazebo/xmlschema/#sensor"
       xmlns:controller="http://playerstage.sourceforge.net/gazebo/xmlschema/#controller"
       xmlns:interface="http://playerstage.sourceforge.net/gazebo/xmlschema/#interface"
       xmlns:xacro="http://ros.org/wiki/xacro" 
       
	   name="robbie">
    <property name="PI" value="3.1415" />  
    <property name="M_PI" value="3.14159"/>
    <property name="M_SCALE" value="0.001"/>
    <property name="MESH_EXT" value="stl"/>
    <xacro:include filename="$(find robbie_description)/urdf/robbie_hardware.xacro" />

<xacro:my_box name="base_link" lwh="0.41 0.35 0.064" xyz="0 0 -0.032" rpy="0 0 0" mass="0.1" material="Gazebo/FlatBlack">
	        <xacro:gold />
        </xacro:my_box>

 <link name="base_footprint">
      <visual>
        <origin xyz="0 0 0" rpy="0 0 0" />
        <geometry>
          <box size="0.05 0.05 0.001" />
        </geometry>
        <material name="TransparentGreen" />
      </visual>
  </link>


  

  <xacro:my_cylinder name="left_wheel" l="0.035" r="0.1025" xyz="0 0 0" rpy="1.57 0 0" mass="0.1" material="Gazebo/Grey">
		<xacro:grey1 />
	</xacro:my_cylinder>

  <xacro:my_cylinder name="right_wheel" l="0.035" r="0.1025" xyz="0 0 0" rpy="1.57 0 0" mass="0.1" material="Gazebo/Grey">
		<xacro:grey1 />
	</xacro:my_cylinder>

  <xacro:my_cylinder name="castor_wheel_l" l="0.035" r="0.04" xyz="0 0 0" rpy="1.57 0 0" mass="0.1" material="Gazebo/Grey">
		<xacro:grey1 />
	</xacro:my_cylinder>

  <xacro:my_cylinder name="castor_wheel_r" l="0.035" r="0.04" xyz="0 0 0" rpy="1.57 0 0" mass="0.1" material="Gazebo/Grey">
		<xacro:grey1 />
	</xacro:my_cylinder>

  <xacro:my_cylinder name="deck_link" l="0.520" r="0.175" xyz="0 0 -0.26" rpy="0 0 0" mass="0.2" material="Gazebo/grey">
			<xacro:black />
		</xacro:my_cylinder>

 <xacro:my_cylinder name="pan_link" l="0.02" r="0.17" xyz="0 0 0" rpy="0 0 0" mass="0.2" material="Gazebo/grey">
			<xacro:blue1 />
		</xacro:my_cylinder>


<!-- ##############################   upper torso   ##################333333-->

<link name="upper_torso" >
   <visual>
      <geometry>
        <mesh filename="package://robbie_description/meshes/chest.stl" scale="${M_SCALE} ${M_SCALE} ${M_SCALE}"/>
      </geometry>
         <xacro:black/>
      <origin rpy="0 0 -1.57" xyz="0.04 0 -0.15"/>
    </visual>
  </link>

<link name="upper_chest" >
   <visual>
      <geometry>
        <mesh filename="package://robbie_description/meshes/chest_cover.stl" scale="${M_SCALE} ${M_SCALE} ${M_SCALE}"/>
      </geometry>
         <xacro:gold/>
      <origin rpy="0 0 1.57" xyz="0 0 -0.085"/>
    </visual>
  </link>

<!-- ##############################   right arm ##################333333--> 
<link name="right_shoulder_tilt" >
   <visual>
      <geometry>
        <mesh filename="package://robbie_description/meshes/right_shoulder_tilt_assy.stl" scale="${M_SCALE} ${M_SCALE} ${M_SCALE}"/>
      </geometry>
       <xacro:black />
      <origin rpy="0 0 1.57" xyz="0 -0.05 -0.05"/>
    </visual>
  </link>

<link name="right_shoulder_lift" >
   <visual>
      <geometry>
        <mesh filename="package://robbie_description/meshes/right_shoulder_assy.stl" scale="${M_SCALE} ${M_SCALE} ${M_SCALE}"/>
      </geometry>
       <xacro:black />
      <origin rpy="-1.57 0 1.57" xyz="-0.01 0 -0.025"/>
    </visual>
  </link>

<link name="right_elbow_link" >
   <visual>
      <geometry>
        <mesh filename="package://robbie_description/meshes/gearbox.stl" scale="${M_SCALE} ${M_SCALE} ${M_SCALE}"/>
      </geometry>
       <xacro:black/>
      <origin rpy="0 0 0" xyz="0 0 0"/>
    </visual>
  </link>

  <link name="right_shoulder_rotate" >
   <visual>
      <geometry>
        <mesh filename="package://robbie_description/meshes/right_upper_arm.stl" scale="${M_SCALE} ${M_SCALE} ${M_SCALE}"/>
      </geometry>
       <xacro:gold/>
      <origin rpy="0 1.57 0" xyz="-0.19 0 0"/>
    </visual>
  </link>

  <link name="right_elbow" >
   <visual>
      <geometry>
        <mesh filename="package://robbie_description/meshes/elbow_pivot.stl" scale="${M_SCALE} ${M_SCALE} ${M_SCALE}"/>
      </geometry>
       <xacro:gold />
      <origin rpy="0 0 3.14" xyz="-0.025 -0.055 -0.02"/>
    </visual>
  </link>

 <link name="right_forearm_link">
    <visual>
      <geometry>
        <mesh filename="package://robbie_description/meshes/fore_arm.stl" scale="${M_SCALE} ${M_SCALE} ${M_SCALE}"/>
      </geometry>
        <xacro:gold />
      <origin rpy="0 1.57 0" xyz="-0.23 0 0"/>
    </visual></link>

  <!-- wrist_yaw_ joint--> 
  <xacro:ax12 name="wrist_yaw_servo" xyz="0 0 0" rpy="-1.57 0 -1.57" />
  <xacro:F3_bracket name="wrist_yaw_servo_bracket_f3" xyz="0 0.005 0" rpy="1.57 0 -1.57" />
   <xacro:F2_bracket name="right_wrist_yaw_bracket_f2" xyz="0 0 0" rpy="-1.57 0 -1.57" />
  
  <!-- wrist_tilt joint-->
  <xacro:ax12 name="wrist_tilt_servo" xyz="0 0 0" rpy="0 -1.57 0" />
  <xacro:F2_bracket name="wrist_tilt_bracket_f2" xyz="0 0 0" rpy="0 -1.57 0" /><!--here-->
 
 <xacro:F3_bracket name="gripper_bracket_f3" xyz="0 0 0" rpy="1.57 0 -1.57" />
  
<!-- Gripper_joint-->
  <xacro:ax12 name="gripper_servo" xyz="0 0 0" rpy="1.57 0 0" />
  <xacro:F2_bracket name="gripper_bracket_f2" xyz="0 0 0" rpy="1.57 0 0" />

  <xacro:my_box name="right_finger_link" lwh="-0.08 0.005 0.035" xyz="-0.04 0 0" rpy="0 0 0" mass="0.1" material="Gazebo/FlatBlack">
	        <xacro:blue1 />
        </xacro:my_box>


  <xacro:my_box name="left_finger_link" lwh="0.08 0.005 0.035" xyz="-0.04 0 0" rpy="0 0 0" mass="0.1" material="Gazebo/FlatBlack">
	        <xacro:grey3/>
        </xacro:my_box>

 
<!-- ##############################   left arm ##################333333--> 
<link name="left_shoulder_tilt" >
   <visual>
      <geometry>
        <mesh filename="package://robbie_description/meshes/left_shoulder_tilt_assy.stl" scale="${M_SCALE} ${M_SCALE} ${M_SCALE}"/>
      </geometry>
       <xacro:black />
      <origin rpy="0 0 1.57" xyz="0 0.0 -0.0"/>
    </visual>
  </link>

  <link name="left_shoulder_lift" >
   <visual>
      <geometry>
        <mesh filename="package://robbie_description/meshes/left_shoulder_assy.stl" scale="${M_SCALE} ${M_SCALE} ${M_SCALE}"/>
      </geometry>
       <xacro:grey1 />
      <origin rpy="-1.57 0 1.57" xyz="0 -0.06 0"/>
    </visual>
  </link>

<link name="left_shoulder_rotate" >
   <visual>
      <geometry>
        <mesh filename="package://robbie_description/meshes/right_upper_arm.stl" scale="${M_SCALE} ${M_SCALE} ${M_SCALE}"/>
      </geometry>
       <xacro:gold/>
      <origin rpy="0 1.57 0" xyz="-0.19 0 0"/>
    </visual>
  </link>


<link name="left_elbow_link" >
   <visual>
      <geometry>
        <mesh filename="package://robbie_description/meshes/gearbox.stl" scale="${M_SCALE} ${M_SCALE} ${M_SCALE}"/>
      </geometry>
       <xacro:black/>
      <origin rpy="0 0 0" xyz="0 0 0"/>
    </visual>
  </link>

<link name="left_elbow" >
   <visual>
      <geometry>
        <mesh filename="package://robbie_description/meshes/elbow_pivot.stl" scale="${M_SCALE} ${M_SCALE} ${M_SCALE}"/>
      </geometry>
       <xacro:gold />
      <origin rpy="0 0 3.14" xyz="-0.025 -0.055 -0.02"/>
    </visual>
  </link>

 <link name="left_forearm_link">
    <visual>
      <geometry>
        <mesh filename="package://robbie_description/meshes/fore_arm.stl" scale="${M_SCALE} ${M_SCALE} ${M_SCALE}"/>
      </geometry>
        <xacro:gold />
      <origin rpy="0 1.57 0" xyz="-0.23 0 0"/>
    </visual>
  </link>

 <!-- left_wrist_pan_ joint--> 
 
  <xacro:F3_bracket name="left_wrist_pan_servo_bracket_f3" xyz="0 0.005 0" rpy="1.57 0 -1.57" />
 <!-- <xacro:F3_bracket name="left_wrist_pan_servo_bracket2_f3" xyz="0 0 0" rpy="0 -1.57 0" />-->
  
 <!-- left_wrist_yaw joint-->
  <xacro:ax12 name="left_wrist_yaw_servo" xyz="0.0 0 0" rpy="-1.57 0 -1.57" />
  <xacro:F2_bracket name="left_wrist_yaw_bracket_f2" xyz="0 0 0" rpy="-1.57 0 -1.57" />
  
  <!-- left_wrist_tilt joint-->
  <xacro:ax12 name="left_wrist_tilt_servo" xyz="0 0 0" rpy="0 -1.57 0" />
  <xacro:F2_bracket name="left_wrist_tilt_bracket_f2" xyz="0 0 0" rpy="0 -1.57 0" />
 
 <xacro:F3_bracket name="left_gripper_bracket_f3" xyz="0 0 0" rpy="1.57 0 -1.57" />
  
<!-- left_Gripper_joint-->
  <xacro:ax12 name="left_gripper_servo" xyz="0 0 0" rpy="1.57 0 0" />
  <xacro:F2_bracket name="left_gripper_bracket_f2" xyz="0 0 0" rpy="1.57 0 0" />

  <xacro:my_box name="left_right_finger_link" lwh="-0.08 0.005 0.035" xyz="-0.04 0 0" rpy="0 0 0" mass="0.1" material="Gazebo/FlatBlack">
	        <xacro:blue1 />
        </xacro:my_box>


  <xacro:my_box name="left_left_finger_link" lwh="0.08 0.005 0.035" xyz="-0.04 0 0" rpy="0 0 0" mass="0.1" material="Gazebo/FlatBlack">
	        <xacro:grey3/>
        </xacro:my_box>


<!-- head details-->
  <xacro:F2_bracket name="head_tilt_bracket" xyz="0 0 0" rpy="0 3.1415 0"/>

  <xacro:ax12 name="head_tilt_link" xyz="0 0 0" rpy="3.1415 0 0">
	</xacro:ax12>

  <xacro:F3_bracket name="head_pan_bracket" xyz="0 0 0" rpy="0 0 0"/>
	
	
  <xacro:ax12 name="head_pan_link" xyz="0 0 0" rpy=" 1.57 0 1.57">
	</xacro:ax12>

  <xacro:F3_bracket name="neck_link" xyz="0 0 0" rpy="1.57 0 -1.570" />

  <xacro:my_box name="head_base_link" lwh="0.06 0.08 0.005" xyz="0 0 0" rpy="0 0 0" mass="0.1" material="Gazebo/FlatBlack">
		<xacro:black />
	</xacro:my_box>

  <link name="head_link" >
   <visual>
      <geometry>
        <mesh filename="package://robbie_description/meshes/head1.stl" scale="${M_SCALE} ${M_SCALE} ${M_SCALE}"/>
      </geometry>
         <material name="gold">
	  <color rgba="0.5 0.3 0 1.0"/>
	</material>
      <origin rpy="0 0 1.57" xyz="0 0 0"/>
    </visual>
  </link>

  <link name="head_link_fake">
      <inertial>
        <mass value="0.0001" />
        <origin xyz="0 0 0" />
        <inertia ixx="0.0001" ixy="0.0" ixz="0.0"
                 iyy="0.0001" iyz="0.0"
                 izz="0.0001" />
      </inertial>
    </link>
  
   <link name="kinect_link">
      <inertial>
        <mass value="1.0" />
        <origin xyz="0 0 0" />
        <inertia ixx="1.0" ixy="0.0" ixz="0.0"
                 iyy="1.0" iyz="0.0"
                 izz="1.0" />
      </inertial>

      <visual>
        <origin xyz=" 0 0 0 " rpy="0 0 0" />
        <geometry>
          <mesh filename="package://robbie_description/meshes/kinect.stl" scale="${M_SCALE} ${M_SCALE} ${M_SCALE}"/>
        </geometry>
        <xacro:ax12_color />
      </visual>

      <collision>
        <origin xyz="0 0 0" rpy="0 0 0" />
        <geometry>
          <mesh filename="package://robbie_description/meshes/kinect.stl" scale="${M_SCALE} ${M_SCALE} ${M_SCALE}"/>
          </geometry>
      </collision>

    </link>

  <link name="head_cam_link">
      <inertial>
        <mass value="1.0" />
        <origin xyz="0 0 0" />
        <inertia ixx="1.0" ixy="0.0" ixz="0.0"
                 iyy="1.0" iyz="0.0"
                 izz="1.0" />
      </inertial>

      <visual>
        <origin xyz=" 0 0 0 " rpy="0 0 0" />
        <geometry>
          <mesh filename="package://robbie_description/meshes/kinect.stl" scale="${M_SCALE} ${M_SCALE} ${M_SCALE}"/>
        </geometry>
        <xacro:ax12_color />
      </visual>

      <collision>
        <origin xyz="0 0 0" rpy="0 0 0" />
        <geometry>
          <mesh filename="package://robbie_description/meshes/kinect.stl" scale="${M_SCALE} ${M_SCALE} ${M_SCALE}"/>
          </geometry>
      </collision>

    </link>

    <xacro:my_cylinder name="camera_link" l="0.035" r="0.01" xyz="0 0 0" rpy="0 1.57 0" mass="0.1" material="Gazebo/Grey">		
      <xacro:grey1 />
	</xacro:my_cylinder>

<!-- virtal joints-->
<link name="right_gripper_link">
    <visual>
      <origin rpy="0 0 0" xyz="0.05 0 0"/>
      <geometry>
        <box size="0.001 0.001 0.001"/>
      </geometry>
    </visual>
    <collision>
      <origin rpy="0 0 0" xyz="0.05 0 0"/>
      <geometry>
        <box size="0.001 0.001 0.001"/>
      </geometry>
    </collision>
  </link>
<link name="left_gripper_link">
    <visual>
      <origin rpy="0 0 0" xyz="-0.05 0 0"/>
      <geometry>
        <box size="0.001 0.001 0.001"/>
      </geometry>
    </visual>
    <collision>
      <origin rpy="0 0 0" xyz="-0.05 0 0"/>
      <geometry>
        <box size="0.001 0.001 0.001"/>
      </geometry>
    </collision>
  </link>


<!-- ##############################   joints ##################333333--> 
<joint name="base_footprint_joint" type="fixed">
    	<parent link="base_footprint" />
    	<child link="base_link" />
    	<origin xyz="-0.1 0 0.08" rpy="0 0 0" />
	</joint> 

<joint name="base_link_joint" type="fixed">
    	<parent link="base_link" />
    	<child link="deck_link" />
    	<origin xyz="0 0 0.51" rpy="0 0 0" />
	</joint>

  <joint name="left_wheel_joint" type="fixed">
    	<parent link="base_link" />
    	<child link="left_wheel" />
    	<origin xyz="0.1 -0.2 -0.04" rpy="0 0 0" />
	</joint>

  <joint name="right_wheel_joint" type="fixed">
    	<parent link="base_link" />
    	<child link="right_wheel" />
    	<origin xyz="0.1 0.2 -0.04" rpy="0 0 0" />
	</joint>

  <joint name="castor_wheel_joint_l" type="fixed">
    	<parent link="base_link" />
    	<child link="castor_wheel_l" />
    	<origin xyz="-0.20 -0.13 -0.1" rpy="0 0 0" />
	</joint>

  <joint name="castor_wheel_joint_r" type="fixed">
    	<parent link="base_link" />
    	<child link="castor_wheel_r" />
    	<origin xyz="-0.20 0.13 -0.1" rpy="0 0 0" />
	</joint>
<!--#################  Upper torso#############################-->
 <joint name="pan_joint" type="revolute">
    	<parent link="deck_link" />
    	<child link="pan_link" />
    	<origin xyz="0.0 0 0" rpy="0 0 0" />
        <axis xyz="0 0 1" />
        <limit lower="-1" upper="1" effort="10" velocity="0" />
	</joint> 

  <joint name="torso_link" type="fixed">
    	<parent link="pan_link" />
    	<child link="upper_torso" />
    	<origin xyz="0.0 0 0.47" rpy="0 0 0" />
	</joint> 

<joint name="chest_link" type="fixed">
    	<parent link="upper_torso" />
    	<child link="upper_chest" />
    	<origin xyz="0.065 0 -0.04" rpy="0 0 0" />
	</joint> 

<joint name="right_arm_tilt_joint" type="revolute">
    	<parent link="upper_torso" />
    	<child link="right_shoulder_tilt" />
    	<origin xyz="0 -0.14 -0.045" rpy="0 0 0" />
        <axis xyz="1 0 0" />
        <limit lower="-1.34" upper="0.1" effort="10" velocity="0" />
	</joint> 

<joint name="right_arm_lift_joint" type="revolute">
    	<parent link="right_shoulder_tilt" />
    	<child link="right_shoulder_lift" />
    	<origin xyz="0 -0.078 -0.042" rpy="0 0 0" />
        <axis xyz="0 1 0" />
        <limit lower="-1.57" upper="1.57" effort="10" velocity="0" />
	</joint> 

<joint name="right_arm_rotate_joint" type="revolute">
    	<parent link="right_shoulder_lift" />
    	<child link="right_shoulder_rotate" />
    	<origin xyz="0.255 0 0" rpy="0 0 0" />
        <axis xyz="1 0 0" />
        <limit lower="-3.14" upper="0.2" effort="10" velocity="0" />
	</joint> 

<joint name="right_elbow_link" type="fixed">
    	<parent link="right_shoulder_rotate" />
    	<child link="right_elbow_link" />
    	<origin xyz="-0.01 0 0.01" rpy="0 0 0" />
        </joint> 

<joint name="right_arm_elbow_joint" type="revolute">
    <parent link="right_elbow_link"/>
    <child link="right_elbow"/>
    <origin xyz="0.01 0.01 0.0" rpy="0 0 0" />
    <axis xyz="0 1 0" />
   <limit lower="-2.20" upper="0.1" effort="10" velocity="0" />
  </joint>

  <joint name="right_arm_forearm_link" type="fixed">
    <parent link="right_elbow"/>
    <child link="right_forearm_link"/>
    <origin xyz="0.31 -0.0 -0.0" rpy="0 0 0" />
  </joint>

  <!--right_arm_wrist_yaw_joint-->
  <joint name="right_arm_wrist_yaw_bracket" type="fixed">
    	<parent link="right_forearm_link" />
    	<child link="wrist_yaw_servo_bracket_f3" />
    	<origin xyz="0.0 0.0 0.0" rpy="0 0 0" />
    	
	</joint>
  <joint name="right_arm_wrist_yaw_bracket1" type="fixed">
    	<parent link="wrist_yaw_servo_bracket_f3" />
    	<child link="wrist_yaw_servo" />
    	<origin xyz="0.04 0 0.0" rpy="0 0 0" />
        <axis xyz="0 0 1" />
    	<limit lower="-2.61" upper="2.61" effort="10" velocity="0" />
      	<dynamics damping="0.0"/>
	</joint>   


   <joint name="right_arm_wrist_yaw_joint" type="revolute">
    	<parent link="wrist_yaw_servo" />
    	<child link="right_wrist_yaw_bracket_f2" />
    	<origin xyz="0.0 0 0.0" rpy="0 0 0" />
        <axis xyz="0 0 1" />
    	<limit lower="-2.61" upper="2.61" effort="10" velocity="0" />
	</joint> 

<joint name="right_arm_wrist_tilt1_bracket" type="fixed">
    	<parent link="right_wrist_yaw_bracket_f2" />
    	<child link="wrist_tilt_bracket_f2" />
    	<origin xyz="0.053 0 0.0" rpy="0 0 0" />
        <axis xyz="0 0 1" />
    	
	</joint> 



<!--wrist_tilt_joint-->
  <joint name="right_arm_wrist_tilt_joint" type="revolute">
    	<parent link="wrist_tilt_bracket_f2" />
    	<child link="wrist_tilt_servo" />
    	<origin xyz="0 0 0" rpy="0 0 0" />
        <axis xyz="0 1 0" />
    	<limit lower="-1.57" upper="1.57" effort="10" velocity="0" />
      	<dynamics damping="0.0"/>
	</joint>

 
  <joint name="right_arm_gripper_bracket" type="fixed">
    	<parent link="wrist_tilt_servo" />
    	<child link="gripper_bracket_f3" />
    	<origin xyz="0.04 0 0.0" rpy="0 0 0" /><!--now-->
	</joint> 

   <joint name="right_arm_gripper_servo" type="fixed">
    	<parent link="gripper_bracket_f3" />
    	<child link="gripper_servo" />
    	<origin xyz="0.02 -0.015 0.0" rpy="0 0 0" />
	</joint>

  <joint name="right_gripper_joint" type="fixed">
    <parent link="gripper_bracket_f3"/>
    <child link="right_gripper_link"/>
    <origin xyz="0.06 -0.01 0" rpy="0 0 0" />
  </joint>


<!-- gripper_joint-->
   <joint name="right_arm_gripper_joint" type="revolute">
    	<parent link="gripper_servo" />
    	<child link="gripper_bracket_f2" />
    	<origin xyz="0 0.0 0.0" rpy="0 0 0" />
        <axis xyz="0 0 1" />
    	<limit lower="-0.1" upper="0.50" effort="10" velocity="0" />
      	<dynamics damping="0.0"/>
	</joint> 



  <joint name="right_arm_finger_link_l" type="fixed">
    	<parent link="gripper_servo" />
    	<child link="left_finger_link" />
    	<origin xyz="0.08 0.04 0" rpy="0 0 0" />
        
	</joint> 
<!-- moving finger   ############-->
  <joint name="right_arm_finger_link_r" type="fixed">
    	<parent link="gripper_bracket_f2" />
    	<child link="right_finger_link" />
    	<origin xyz="0.08 -0.03 0" rpy="0 0 0" />
	</joint>

 
	
<!--##########################        left arm             #############################-->
<joint name="left_arm_tilt_joint" type="revolute">
    	<parent link="upper_torso" />
    	<child link="left_shoulder_tilt" />
    	<origin xyz="0.003 0.142 -0.05" rpy="0 0 0" />
        <axis xyz="-1 0 0" />
        <limit lower="-1.34" upper="0.1" effort="10" velocity="0" />
	</joint> 

<joint name="left_arm_lift_joint" type="revolute">
    	<parent link="left_shoulder_tilt" />
    	<child link="left_shoulder_lift" />
    	<origin xyz="0 0.08 -0.04" rpy="0 0 0" />
        <axis xyz="0 1 0" />
        <limit lower="-1.57" upper="1.57" effort="10" velocity="0" />
	</joint> 

<joint name="left_arm_rotate_joint" type="revolute">
    	<parent link="left_shoulder_lift" />
    	<child link="left_shoulder_rotate" />
    	<origin xyz="0.24 0 0" rpy="0 0 0" />
        <axis xyz="1 0 0" />
        <limit lower="-0.2" upper="3.14" effort="10" velocity="0" />
	</joint> 

<joint name="left_elbow_link" type="fixed">
    	<parent link="left_shoulder_rotate" />
    	<child link="left_elbow_link" />
    	<origin xyz="-0.01 0 0.008" rpy="0 0 0" />
	</joint> 

<joint name="left_arm_elbow_joint" type="revolute">
    <parent link="left_elbow_link"/>
    <child link="left_elbow"/>
    <origin xyz="0 0 0" rpy="0 -0 0" />
    <axis xyz="0 1 0" />
   <limit lower="-2.20" upper="0.17" effort="10" velocity="0" />
  </joint>


 <joint name="left_arm_forearm_link" type="fixed">
    <parent link="left_elbow"/>
    <child link="left_forearm_link"/>
    <origin xyz="0.31 -0.0 -0.0" rpy="0 0 0" />
  </joint>

    
    	
  <joint name="left_arm_wrist_yaw_attach" type="fixed"> <!--revolute-->
    	<parent link="left_forearm_link" />
    	<child link="left_wrist_pan_servo_bracket_f3" />
    	<origin xyz="0. 0 0" rpy="0 0 0" />
      	<dynamics damping="0.0"/>
	</joint>   


   <joint name="left_arm_wrist_tilt_bracket" type="fixed">
    	<parent link="left_wrist_pan_servo_bracket_f3" />
    	<child link="left_wrist_yaw_servo" />
    	<origin xyz="0.04 0 0.0" rpy="0 0 0" />
        <axis xyz="1 0 0" />
    	
	</joint> 


<!--wrist_yaw_joint-->
  <joint name="left_arm_wrist_yaw_joint" type="revolute"> <!--revolute-->
    	<parent link="left_wrist_yaw_servo" />
    	<child link="left_wrist_yaw_bracket_f2" />
    	<origin xyz="0.0 0 0" rpy="0 0 0" />
        <axis xyz="0 0 1" />
    	<limit lower="-1.57" upper="1.57" effort="10" velocity="0" />
      	<dynamics damping="0.0"/>
	</joint>

  <joint name="left_arm_wrist_yaw_bracket" type="fixed">
    	<parent link="left_wrist_yaw_bracket_f2" />
    	<child link="left_wrist_tilt_bracket_f2" />
    	<origin xyz="0.055 0 0.0" rpy="0 0 0" />
        <axis xyz="1 0 0" />
    	<limit lower="-1.57" upper="1.57" effort="10" velocity="0" />
      	<dynamics damping="0.0"/>
        </joint> 

  <!--wrist_tilt_joint-->
  <joint name="left_arm_wrist_tilt_joint" type="revolute"> <!--revolute-->
    	<parent link="left_wrist_tilt_bracket_f2" />
    	<child link="left_wrist_tilt_servo" />
    	<origin xyz="-0 -0.0 0" rpy="0 0 0" />
        <axis xyz="0 1 0" />
    	<limit lower="-1.57" upper="1.57" effort="10" velocity="0" />
      	<dynamics damping="0.0"/>
	</joint>

 
  <joint name="left_arm_gripper_bracket" type="fixed">
    	<parent link="left_wrist_tilt_servo" />
    	<child link="left_gripper_bracket_f3" />
    	<origin xyz="0.04 0 0.0" rpy="0 0 0" />
	</joint> 

   <joint name="left_arm_gripper_servo" type="fixed">
    	<parent link="left_gripper_bracket_f3" />
    	<child link="left_gripper_servo" />
    	<origin xyz="0.02 -0.02 -0." rpy="0 0 0" />
	</joint>

  <joint name="left_gripper_joint" type="fixed">
    <origin rpy="0 0 0" xyz="0.06 -0.01 0"/>
    <parent link="left_gripper_bracket_f3"/>
    <child link="left_gripper_link"/>
  </joint>

  <!-- left gripper_joint-->
   <joint name="left_arm_gripper_joint" type="revolute"> <!--revolute-->
    	<parent link="left_gripper_servo" />
    	<child link="left_gripper_bracket_f2" />
    	<origin xyz="0 0.0 0.0" rpy="0 0 0" />
        <axis xyz="0 0 1" />
    	<limit lower="-1.0" upper="0.3" effort="10" velocity="0" />
      	<dynamics damping="0.0"/>
	</joint> 

  <joint name="left_arm_finger_link_l" type="fixed">
    	<parent link="left_gripper_servo" />
    	<child link="left_left_finger_link" />
    	<origin xyz="0.08 0.04 0" rpy="0 0 0" />
        
	</joint> 

  <joint name="left_arm_finger_link_r" type="fixed">
    	<parent link="left_gripper_bracket_f2" />
    	<child link="left_right_finger_link" />
    	<origin xyz="0.08 -0.03 0" rpy="0 0 0" />
	</joint>

<!-- #####################################Head joints#########################################-->
  <joint name="head_tilt_servo" type="fixed">
    	<parent link="upper_torso" />
    	<child link="head_tilt_bracket" />
    	<origin xyz="-0.0 0. 0.05" rpy="0 0 0" />
	</joint>
<!-- Head tilt joint-->
  <joint name="head_tilt_mod_joint" type="revolute">
    	<parent link="head_tilt_bracket" />
    	<child link="head_tilt_link" />
    	<origin xyz="0 0 0.0" rpy="0 0 0" />
    	<axis xyz="0 1 0" />
    	<limit lower="-2.6" upper="2.6" effort="10" velocity="0" />
      	<dynamics damping="0.0"/>
	</joint>

<!-- Head tilt joint fake-->
  <joint name="head_tilt_joint" type="fixed">
    	<parent link="head_tilt_bracket" />
    	<child link="head_link_fake" />
    	<origin xyz="0 0 0.0" rpy="0 0 0" />
    	<axis xyz="0 1 0" />
    	<limit lower="-2.6" upper="2.6" effort="10" velocity="0" />
      	<dynamics damping="0.0"/>
	</joint>

  <joint name="head_pan_servo" type="fixed">
    	<parent link="head_tilt_link" />
    	<child link="head_pan_bracket" />
    	<origin xyz="-0.0 0 0.04" rpy="0 0 0" />
	</joint>

  <!-- head_pan_joint-->	
	<joint name="head_pan_joint" type="revolute">
    	<parent link="head_pan_bracket" />
    	<child link="head_pan_link" />
    	<origin xyz="0.0 0 0.02" rpy="0 0 0" />
        <origin xyz="0 0 0.0" rpy="0 0 0" />
    	<axis xyz="0 0 1" />
    	<limit lower="-2" upper="2" effort="10" velocity="0" />
      	<dynamics damping="0.0"/>
	</joint>

  <joint name="head_neck_link" type="fixed">
    	<parent link="head_pan_link" />
    	<child link="neck_link" />
    	<origin xyz="-0.04 0 0.0" rpy="0 0 0" />
	</joint>

  <joint name="neck_joint" type="fixed">
    	<parent link="neck_link" />
    	<child link="head_base_link" />
    	<origin xyz="0.02 0 0.0" rpy="0 0 0" />
	</joint>
	
  <joint name="head_joint" type="fixed">
    	<parent link="head_base_link" />
    	<child link="head_link" />
    	<origin xyz="-0.02 -0.097 0" rpy="0 0 0" />
	</joint>

   <joint name="camera_link" type="fixed">
    	<parent link="head_link" />
    	<child link="camera_link" />
    	<origin xyz="0.13 0.1 0.6" rpy="0 0 0" />
	</joint>
  


  <joint name="kinect_joint" type="fixed">
    	<parent link="base_link" />
    	<child link="kinect_link" />
    	<origin xyz="0.2 0 0.33" rpy="0 0 0" />
	</joint>
<joint name="kinect_depth_joint" type="fixed">
         <origin xyz="0 0.0125 0.015" rpy="0 0 0" />
          <parent link="kinect_link" />
          <child link="kinect_depth_frame" />
      </joint>

      <link name="kinect_depth_frame">
      <inertial>
         <mass value="0.000001" />
         <origin xyz="0 0 0" />
         <inertia ixx="0.0001" ixy="0.0" ixz="0.0"
            iyy="0.0001" iyz="0.0"
            izz="0.0001" />
         </inertial>
      </link>

      <joint name="kinect_depth_optical_joint" type="fixed">
         <origin xyz="0 0 0" rpy="${-PI/2} 0 ${-PI/2}" />
         <parent link="kinect_depth_frame" />
         <child link="kinect_depth_optical_frame" />
      </joint>

      <link name="kinect_depth_optical_frame">
         <inertial>
            <mass value="0.000001" />
            <origin xyz="0 0 0" />
            <inertia ixx="0.0001" ixy="0.0" ixz="0.0"
               iyy="0.0001" iyz="0.0"
               izz="0.0001" />
         </inertial>
      </link>

      <joint name="kinect_rgb_joint" type="fixed">
         <origin xyz="0 -0.0125 0.015" rpy="0 0 0" />
         <parent link="kinect_link" />
         <child link="kinect_rgb_frame" />
      </joint>

      <link name="kinect_rgb_frame">
         <inertial>
         <mass value="0.000001" />
         <origin xyz="0 0 0" />
         <inertia ixx="0.0001" ixy="0.0" ixz="0.0"
            iyy="0.0001" iyz="0.0"
            izz="0.0001" />
         </inertial>
      </link>

      <joint name="kinect_rgb_optical_joint" type="fixed">
         <origin xyz="0 0 0" rpy="${-PI/2} 0 ${-PI/2}" />
         <parent link="kinect_rgb_frame" />
         <child link="kinect_rgb_optical_frame" />
      </joint>

      <link name="kinect_rgb_optical_frame">
         <inertial>
            <mass value="0.000001" />
            <origin xyz="0 0 0" />
            <inertia ixx="0.0001" ixy="0.0" ixz="0.0"
               iyy="0.0001" iyz="0.0"
               izz="0.0001" />
         </inertial>
      </link>

  <joint name="head_cam_joint" type="fixed">
    	<parent link="head_link" />
    	<child link="head_cam_link" />
    	<origin xyz="0.15 0.11 0.13" rpy="0 0 0" />
	</joint>
<joint name="head_cam_depth_joint" type="fixed">
         <origin xyz="0 0.0125 0.015" rpy="0 0 0" />
          <parent link="head_cam_link" />
          <child link="head_cam_depth_frame" />
      </joint>

      <link name="head_cam_depth_frame">
      <inertial>
         <mass value="0.000001" />
         <origin xyz="0 0 0" />
         <inertia ixx="0.0001" ixy="0.0" ixz="0.0"
            iyy="0.0001" iyz="0.0"
            izz="0.0001" />
         </inertial>
      </link>

      <joint name="head_cam_depth_optical_joint" type="fixed">
         <origin xyz="0 0 0" rpy="${-PI/2} 0 ${-PI/2}" />
         <parent link="head_cam_depth_frame" />
         <child link="head_cam_depth_optical_frame" />
      </joint>

      <link name="head_cam_depth_optical_frame">
         <inertial>
            <mass value="0.000001" />
            <origin xyz="0 0 0" />
            <inertia ixx="0.0001" ixy="0.0" ixz="0.0"
               iyy="0.0001" iyz="0.0"
               izz="0.0001" />
         </inertial>
      </link>

      <joint name="head_cam_rgb_joint" type="fixed">
         <origin xyz="0 -0.0125 0.015" rpy="0 0 0" />
         <parent link="head_cam_link" />
         <child link="head_cam_rgb_frame" />
      </joint>

      <link name="head_cam_rgb_frame">
         <inertial>
         <mass value="0.000001" />
         <origin xyz="0 0 0" />
         <inertia ixx="0.0001" ixy="0.0" ixz="0.0"
            iyy="0.0001" iyz="0.0"
            izz="0.0001" />
         </inertial>
      </link>

      <joint name="head_cam_rgb_optical_joint" type="fixed">
         <origin xyz="0 0 0" rpy="${-PI/2} 0 ${-PI/2}" />
         <parent link="head_cam_rgb_frame" />
         <child link="head_cam_rgb_optical_frame" />
      </joint>

      <link name="head_cam_rgb_optical_frame">
         <inertial>
            <mass value="0.000001" />
            <origin xyz="0 0 0" />
            <inertia ixx="0.0001" ixy="0.0" ixz="0.0"
               iyy="0.0001" iyz="0.0"
               izz="0.0001" />
         </inertial>
      </link>
  
	


<gazebo reference="robbie">
  	</gazebo>
</robot>
