<?xml version="1.0" ?>
<!-- =================================================================================== -->
<!-- |    This document was autogenerated by xacro from rob_inmoov.xacro               | -->
<!-- |    EDITING THIS FILE BY HAND IS NOT RECOMMENDED                                 | -->
<!-- =================================================================================== -->
<!-- XML namespaces -->
<robot name="robbie" xmlns:controller="http://playerstage.sourceforge.net/gazebo/xmlschema/#controller" xmlns:interface="http://playerstage.sourceforge.net/gazebo/xmlschema/#interface" xmlns:sensor="http://playerstage.sourceforge.net/gazebo/xmlschema/#sensor" xmlns:xacro="http://ros.org/wiki/xacro">
  <link name="base_link">
    <visual>
      <origin rpy="0 0 0" xyz="0 0 .135"/>
      <geometry>
        <box size="0.41 0.35 0.06"/>
      </geometry>
      <material name="gold">
        <color rgba="0.5 0.3 0 1.0"/>
      </material>
    </visual>
    <collision>
      <origin rpy="0 0 0" xyz="0 0 .135"/>
      <geometry>
        <box size="0.41 0.35 0.06"/>
      </geometry>
    </collision>
  </link>
  <gazebo reference="base_link">
    <material>Gazebo/FlatBlack</material>
    <selfCollide>false</selfCollide>
    <turnGravityOff>true</turnGravityOff>
  </gazebo>
  <link name="base_footprint">
    <visual>
      <origin rpy="0 0 0" xyz="0 0 0"/>
      <geometry>
        <box size="0.05 0.05 0.001"/>
      </geometry>
      <material name="TransparentGreen"/>
    </visual>
  </link>
  <link name="left_wheel">
    <visual>
      <origin rpy="1.57 0 0" xyz="0 0 0"/>
      <geometry>
        <cylinder length="0.035" radius="0.1025"/>
      </geometry>
      <material name="grey1">
        <color rgba="0.75 0.75 0.75 1.0"/>
      </material>
    </visual>
    <collision>
      <origin rpy="1.57 0 0" xyz="0 0 0"/>
      <geometry>
        <cylinder length="0.035" radius="0.1025"/>
      </geometry>
    </collision>
    <inertial>
      <mass value="0.1"/>
      <inertia ixx="0.001" ixy="0.0" ixz="0.0" iyy="0.001" iyz="0.0" izz="0.001"/>
    </inertial>
  </link>
  <gazebo reference="left_wheel">
    <material>Gazebo/Grey</material>
    <selfCollide>false</selfCollide>
    <turnGravityOff>true</turnGravityOff>
  </gazebo>
  <link name="right_wheel">
    <visual>
      <origin rpy="1.57 0 0" xyz="0 0 0"/>
      <geometry>
        <cylinder length="0.035" radius="0.1025"/>
      </geometry>
      <material name="grey1">
        <color rgba="0.75 0.75 0.75 1.0"/>
      </material>
    </visual>
    <collision>
      <origin rpy="1.57 0 0" xyz="0 0 0"/>
      <geometry>
        <cylinder length="0.035" radius="0.1025"/>
      </geometry>
    </collision>
    <inertial>
      <mass value="0.1"/>
      <inertia ixx="0.001" ixy="0.0" ixz="0.0" iyy="0.001" iyz="0.0" izz="0.001"/>
    </inertial>
  </link>
  <gazebo reference="right_wheel">
    <material>Gazebo/Grey</material>
    <selfCollide>false</selfCollide>
    <turnGravityOff>true</turnGravityOff>
  </gazebo>
  <link name="castor_wheel_l">
    <visual>
      <origin rpy="1.57 0 0" xyz="0 0 0"/>
      <geometry>
        <cylinder length="0.035" radius="0.04"/>
      </geometry>
      <material name="grey1">
        <color rgba="0.75 0.75 0.75 1.0"/>
      </material>
    </visual>
    <collision>
      <origin rpy="1.57 0 0" xyz="0 0 0"/>
      <geometry>
        <cylinder length="0.035" radius="0.04"/>
      </geometry>
    </collision>
    <inertial>
      <mass value="0.1"/>
      <inertia ixx="0.001" ixy="0.0" ixz="0.0" iyy="0.001" iyz="0.0" izz="0.001"/>
    </inertial>
  </link>
  <gazebo reference="castor_wheel_l">
    <material>Gazebo/Grey</material>
    <selfCollide>false</selfCollide>
    <turnGravityOff>true</turnGravityOff>
  </gazebo>
  <link name="castor_wheel_r">
    <visual>
      <origin rpy="1.57 0 0" xyz="0 0 0"/>
      <geometry>
        <cylinder length="0.035" radius="0.04"/>
      </geometry>
      <material name="grey1">
        <color rgba="0.75 0.75 0.75 1.0"/>
      </material>
    </visual>
    <collision>
      <origin rpy="1.57 0 0" xyz="0 0 0"/>
      <geometry>
        <cylinder length="0.035" radius="0.04"/>
      </geometry>
    </collision>
    <inertial>
      <mass value="0.1"/>
      <inertia ixx="0.001" ixy="0.0" ixz="0.0" iyy="0.001" iyz="0.0" izz="0.001"/>
    </inertial>
  </link>
  <gazebo reference="castor_wheel_r">
    <material>Gazebo/Grey</material>
    <selfCollide>false</selfCollide>
    <turnGravityOff>true</turnGravityOff>
  </gazebo>
  <link name="deck_link">
    <visual>
      <origin rpy="0 0 0" xyz="0.1 0 0"/>
      <geometry>
        <cylinder length="0.52" radius="0.175"/>
      </geometry>
      <material name="black">
        <color rgba="0.1 0.1 0.1 1.0"/>
      </material>
    </visual>
    <collision>
      <origin rpy="0 0 0" xyz="0.1 0 0"/>
      <geometry>
        <cylinder length="0.52" radius="0.175"/>
      </geometry>
    </collision>
    <inertial>
      <mass value="0.2"/>
      <inertia ixx="0.001" ixy="0.0" ixz="0.0" iyy="0.001" iyz="0.0" izz="0.001"/>
    </inertial>
  </link>
  <gazebo reference="deck_link">
    <material>Gazebo/grey</material>
    <selfCollide>false</selfCollide>
    <turnGravityOff>true</turnGravityOff>
  </gazebo>
  <link name="pan_link">
    <visual>
      <origin rpy="0 0 0" xyz="0 0 0"/>
      <geometry>
        <cylinder length="0.02" radius="0.17"/>
      </geometry>
      <material name="blue1">
        <color rgba="0 0 0.9 1.0"/>
      </material>
    </visual>
    <collision>
      <origin rpy="0 0 0" xyz="0 0 0"/>
      <geometry>
        <cylinder length="0.02" radius="0.17"/>
      </geometry>
    </collision>
    <inertial>
      <mass value="0.2"/>
      <inertia ixx="0.001" ixy="0.0" ixz="0.0" iyy="0.001" iyz="0.0" izz="0.001"/>
    </inertial>
  </link>
  <gazebo reference="pan_link">
    <material>Gazebo/grey</material>
    <selfCollide>false</selfCollide>
    <turnGravityOff>true</turnGravityOff>
  </gazebo>
  <!-- ##############################   upper torso   ##################333333-->
  <link name="upper_torso">
    <visual>
      <geometry>
        <mesh filename="package://robbie_description/meshes/chest.stl" scale="0.001 0.001 0.001"/>
      </geometry>
      <material name="black">
        <color rgba="0.1 0.1 0.1 1.0"/>
      </material>
      <origin rpy="0 0 -1.57" xyz="0 0 0"/>
    </visual>
  </link>
  <link name="upper_chest">
    <visual>
      <geometry>
        <mesh filename="package://robbie_description/meshes/chest_cover.stl" scale="0.001 0.001 0.001"/>
      </geometry>
      <material name="gold">
        <color rgba="0.5 0.3 0 1.0"/>
      </material>
      <origin rpy="0 0 1.57" xyz="0 0 0"/>
    </visual>
  </link>
  <!-- ##############################   right arm ##################333333-->
  <link name="right_shoulder_tilt">
    <visual>
      <geometry>
        <mesh filename="package://robbie_description/meshes/right_shoulder_tilt_assy.stl" scale="0.001 0.001 0.001"/>
      </geometry>
      <material name="black">
        <color rgba="0.1 0.1 0.1 1.0"/>
      </material>
      <origin rpy="0 0 1.57" xyz="0 -0.05 -0.05"/>
    </visual>
  </link>
  <link name="right_shoulder_lift">
    <visual>
      <geometry>
        <mesh filename="package://robbie_description/meshes/right_shoulder_assy.stl" scale="0.001 0.001 0.001"/>
      </geometry>
      <material name="black">
        <color rgba="0.1 0.1 0.1 1.0"/>
      </material>
      <origin rpy="0 0 1.57" xyz="-0.025 0 0.01"/>
    </visual>
  </link>
  <link name="right_elbow_link">
    <visual>
      <geometry>
        <mesh filename="package://robbie_description/meshes/gearbox.stl" scale="0.001 0.001 0.001"/>
      </geometry>
      <material name="black">
        <color rgba="0.1 0.1 0.1 1.0"/>
      </material>
      <origin rpy="0 1.57 0" xyz="0 0 0"/>
    </visual>
  </link>
  <link name="right_shoulder_rotate">
    <visual>
      <geometry>
        <mesh filename="package://robbie_description/meshes/right_upper_arm.stl" scale="0.001 0.001 0.001"/>
      </geometry>
      <material name="gold">
        <color rgba="0.5 0.3 0 1.0"/>
      </material>
      <origin rpy="0 3.14 0" xyz="0 0 0"/>
    </visual>
  </link>
  <link name="right_elbow">
    <visual>
      <geometry>
        <mesh filename="package://robbie_description/meshes/elbow_pivot.stl" scale="0.001 0.001 0.001"/>
      </geometry>
      <material name="gold">
        <color rgba="0.5 0.3 0 1.0"/>
      </material>
      <origin rpy="3.14 0 0" xyz="0.025 -0.05 0.03"/>
    </visual>
  </link>
  <link name="right_forearm_link">
    <visual>
      <geometry>
        <mesh filename="package://robbie_description/meshes/fore_arm.stl" scale="0.001 0.001 0.001"/>
      </geometry>
      <material name="gold">
        <color rgba="0.5 0.3 0 1.0"/>
      </material>
      <origin rpy="0 -1.57 0" xyz="0 0 0"/>
    </visual>
  </link>
  <!-- wrist_pan_ joint-->
  <link name="wrist_pan_servo">
    <visual>
      <origin rpy="0 0 0" xyz="0 0 0"/>
      <geometry>
        <mesh filename="package://robbie/meshes/ax12_box2.stl" scale="0.001 0.001 0.001"/>
      </geometry>
      <material name="ax12_color">
        <color rgba="0.1 0.1 0.1 1.0"/>
      </material>
    </visual>
    <collision>
      <origin rpy="0 0 0" xyz="0 0 0"/>
      <geometry>
        <!--<box size="0.032 0.038 0.05" />-->
        <mesh filename="package://robbie/meshes/ax12_box2.stl" scale="0.001 0.001 0.001"/>
      </geometry>
    </collision>
    <inertial>
      <mass value="0.055"/>
      <inertia ixx="0.001" ixy="0.0" ixz="0.0" iyy="0.001" iyz="0.0" izz="0.001"/>
    </inertial>
  </link>
  <gazebo reference="wrist_pan_servo">
    <material>Gazebo/FlatBlack</material>
    <selfCollide>false</selfCollide>
    <turnGravityOff>true</turnGravityOff>
  </gazebo>
  <link name="wrist_pan_servo_bracket_f3">
    <visual>
      <origin rpy="1.57 0 0" xyz="0 0.005 0"/>
      <geometry>
        <mesh filename="package://robbie/meshes/F3.stl" scale="0.001 0.001 0.001"/>
      </geometry>
      <material name="grey1">
        <color rgba="0.75 0.75 0.75 1.0"/>
      </material>
      <material name="bracket_color">
        <color rgba="0.9 0.9 0.9 1.0"/>
      </material>
    </visual>
    <collision>
      <origin rpy="1.57 0 0" xyz="0 0.005 0"/>
      <geometry>
        <mesh filename="package://robbie/meshes/F3.stl" scale="0.001 0.001 0.001"/>
      </geometry>
    </collision>
    <inertial>
      <mass value="0.01"/>
      <inertia ixx="0.001" ixy="0.0" ixz="0.0" iyy="0.001" iyz="0.0" izz="0.001"/>
    </inertial>
  </link>
  <gazebo reference="wrist_pan_servo_bracket_f3">
    <material>Gazebo/WhiteEmissive</material>
    <selfCollide>false</selfCollide>
    <turnGravityOff>true</turnGravityOff>
  </gazebo>
  <!-- <xacro:F3_bracket name="wrist_pan_servo_bracket2_f3" xyz="0 0 0" rpy="0 -1.57 0" />-->
  <!-- wrist_tilt joint-->
  <link name="wrist_tilt_servo">
    <visual>
      <origin rpy="-1.57 0 0" xyz="-0.04 0.05 0"/>
      <geometry>
        <mesh filename="package://robbie/meshes/ax12_box2.stl" scale="0.001 0.001 0.001"/>
      </geometry>
      <material name="ax12_color">
        <color rgba="0.1 0.1 0.1 1.0"/>
      </material>
    </visual>
    <collision>
      <origin rpy="-1.57 0 0" xyz="-0.04 0.05 0"/>
      <geometry>
        <!--<box size="0.032 0.038 0.05" />-->
        <mesh filename="package://robbie/meshes/ax12_box2.stl" scale="0.001 0.001 0.001"/>
      </geometry>
    </collision>
    <inertial>
      <mass value="0.055"/>
      <inertia ixx="0.001" ixy="0.0" ixz="0.0" iyy="0.001" iyz="0.0" izz="0.001"/>
    </inertial>
  </link>
  <gazebo reference="wrist_tilt_servo">
    <material>Gazebo/FlatBlack</material>
    <selfCollide>false</selfCollide>
    <turnGravityOff>true</turnGravityOff>
  </gazebo>
  <link name="wrist_tilt_bracket_f2">
    <visual>
      <origin rpy="0 1.57 0" xyz="0 0 0"/>
      <geometry>
        <mesh filename="package://robbie/meshes/F2.stl" scale="0.001 0.001 0.001"/>
      </geometry>
      <material name="bracket_color">
        <color rgba="0.9 0.9 0.9 1.0"/>
      </material>
    </visual>
    <collision>
      <origin rpy="0 1.57 0" xyz="0 0 0"/>
      <geometry>
        <mesh filename="package://robbie/meshes/F2.stl" scale="0.001 0.001 0.001"/>
      </geometry>
    </collision>
    <inertial>
      <mass value="0.02"/>
      <inertia ixx="0.001" ixy="0.0" ixz="0.0" iyy="0.001" iyz="0.0" izz="0.001"/>
    </inertial>
  </link>
  <gazebo reference="wrist_tilt_bracket_f2">
    <material>Gazebo/WhiteEmissive</material>
    <selfCollide>false</selfCollide>
    <turnGravityOff>true</turnGravityOff>
  </gazebo>
  <!--here-->
  <link name="gripper_bracket_f3">
    <visual>
      <origin rpy="1.57 1.57 0" xyz="0 0 0"/>
      <geometry>
        <mesh filename="package://robbie/meshes/F3.stl" scale="0.001 0.001 0.001"/>
      </geometry>
      <material name="grey1">
        <color rgba="0.75 0.75 0.75 1.0"/>
      </material>
      <material name="bracket_color">
        <color rgba="0.9 0.9 0.9 1.0"/>
      </material>
    </visual>
    <collision>
      <origin rpy="1.57 1.57 0" xyz="0 0 0"/>
      <geometry>
        <mesh filename="package://robbie/meshes/F3.stl" scale="0.001 0.001 0.001"/>
      </geometry>
    </collision>
    <inertial>
      <mass value="0.01"/>
      <inertia ixx="0.001" ixy="0.0" ixz="0.0" iyy="0.001" iyz="0.0" izz="0.001"/>
    </inertial>
  </link>
  <gazebo reference="gripper_bracket_f3">
    <material>Gazebo/WhiteEmissive</material>
    <selfCollide>false</selfCollide>
    <turnGravityOff>true</turnGravityOff>
  </gazebo>
  <!-- Gripper_joint-->
  <link name="gripper_servo">
    <visual>
      <origin rpy="1.57 0 0" xyz="0 0 0"/>
      <geometry>
        <mesh filename="package://robbie/meshes/ax12_box2.stl" scale="0.001 0.001 0.001"/>
      </geometry>
      <material name="ax12_color">
        <color rgba="0.1 0.1 0.1 1.0"/>
      </material>
    </visual>
    <collision>
      <origin rpy="1.57 0 0" xyz="0 0 0"/>
      <geometry>
        <!--<box size="0.032 0.038 0.05" />-->
        <mesh filename="package://robbie/meshes/ax12_box2.stl" scale="0.001 0.001 0.001"/>
      </geometry>
    </collision>
    <inertial>
      <mass value="0.055"/>
      <inertia ixx="0.001" ixy="0.0" ixz="0.0" iyy="0.001" iyz="0.0" izz="0.001"/>
    </inertial>
  </link>
  <gazebo reference="gripper_servo">
    <material>Gazebo/FlatBlack</material>
    <selfCollide>false</selfCollide>
    <turnGravityOff>true</turnGravityOff>
  </gazebo>
  <link name="gripper_bracket_f2">
    <visual>
      <origin rpy="0 0 1.57" xyz="0 0 0"/>
      <geometry>
        <mesh filename="package://robbie/meshes/F2.stl" scale="0.001 0.001 0.001"/>
      </geometry>
      <material name="bracket_color">
        <color rgba="0.9 0.9 0.9 1.0"/>
      </material>
    </visual>
    <collision>
      <origin rpy="0 0 1.57" xyz="0 0 0"/>
      <geometry>
        <mesh filename="package://robbie/meshes/F2.stl" scale="0.001 0.001 0.001"/>
      </geometry>
    </collision>
    <inertial>
      <mass value="0.02"/>
      <inertia ixx="0.001" ixy="0.0" ixz="0.0" iyy="0.001" iyz="0.0" izz="0.001"/>
    </inertial>
  </link>
  <gazebo reference="gripper_bracket_f2">
    <material>Gazebo/WhiteEmissive</material>
    <selfCollide>false</selfCollide>
    <turnGravityOff>true</turnGravityOff>
  </gazebo>
  <link name="right_finger_link">
    <visual>
      <origin rpy="1.57 0 1.57" xyz="0 0 0"/>
      <geometry>
        <box size="-0.08 0.005 0.035"/>
      </geometry>
      <material name="blue1">
        <color rgba="0 0 0.9 1.0"/>
      </material>
    </visual>
    <collision>
      <origin rpy="1.57 0 1.57" xyz="0 0 0"/>
      <geometry>
        <box size="-0.08 0.005 0.035"/>
      </geometry>
    </collision>
  </link>
  <gazebo reference="right_finger_link">
    <material>Gazebo/FlatBlack</material>
    <selfCollide>false</selfCollide>
    <turnGravityOff>true</turnGravityOff>
  </gazebo>
  <link name="left_finger_link">
    <visual>
      <origin rpy="1.57 0 1.57" xyz="0 0 0"/>
      <geometry>
        <box size="0.08 0.005 0.035"/>
      </geometry>
      <material name="grey3">
        <color rgba="0.8 0.8 0.8 1.0"/>
      </material>
    </visual>
    <collision>
      <origin rpy="1.57 0 1.57" xyz="0 0 0"/>
      <geometry>
        <box size="0.08 0.005 0.035"/>
      </geometry>
    </collision>
  </link>
  <gazebo reference="left_finger_link">
    <material>Gazebo/FlatBlack</material>
    <selfCollide>false</selfCollide>
    <turnGravityOff>true</turnGravityOff>
  </gazebo>
  <!-- ##############################   left arm ##################333333-->
  <link name="left_shoulder_tilt">
    <visual>
      <geometry>
        <mesh filename="package://robbie_description/meshes/left_shoulder_tilt_assy.stl" scale="0.001 0.001 0.001"/>
      </geometry>
      <material name="black">
        <color rgba="0.1 0.1 0.1 1.0"/>
      </material>
      <origin rpy="0 0 1.57" xyz="0 0.0 -0.0"/>
    </visual>
  </link>
  <link name="left_shoulder_lift">
    <visual>
      <geometry>
        <mesh filename="package://robbie_description/meshes/left_shoulder_assy.stl" scale="0.001 0.001 0.001"/>
      </geometry>
      <material name="black">
        <color rgba="0.1 0.1 0.1 1.0"/>
      </material>
      <origin rpy="0 0 1.57" xyz="0 0 0"/>
    </visual>
  </link>
  <link name="left_shoulder_rotate">
    <visual>
      <geometry>
        <mesh filename="package://robbie_description/meshes/right_upper_arm.stl" scale="0.001 0.001 0.001"/>
      </geometry>
      <material name="gold">
        <color rgba="0.5 0.3 0 1.0"/>
      </material>
      <origin rpy="0 3.14 0" xyz="0 0 0"/>
    </visual>
  </link>
  <link name="left_elbow_link">
    <visual>
      <geometry>
        <mesh filename="package://robbie_description/meshes/gearbox.stl" scale="0.001 0.001 0.001"/>
      </geometry>
      <material name="black">
        <color rgba="0.1 0.1 0.1 1.0"/>
      </material>
      <origin rpy="0 1.57 0" xyz="0 0 0"/>
    </visual>
  </link>
  <link name="left_elbow">
    <visual>
      <geometry>
        <mesh filename="package://robbie_description/meshes/elbow_pivot.stl" scale="0.001 0.001 0.001"/>
      </geometry>
      <material name="gold">
        <color rgba="0.5 0.3 0 1.0"/>
      </material>
      <origin rpy="3.14 0 0" xyz="0.025 -0.05 0.03"/>
    </visual>
  </link>
  <link name="left_forearm_link">
    <visual>
      <geometry>
        <mesh filename="package://robbie_description/meshes/fore_arm.stl" scale="0.001 0.001 0.001"/>
      </geometry>
      <material name="gold">
        <color rgba="0.5 0.3 0 1.0"/>
      </material>
      <origin rpy="0 -1.57 0" xyz="0 0 0"/>
    </visual>
  </link>
  <!-- left_wrist_pan_ joint-->
  <link name="left_wrist_pan_servo">
    <visual>
      <origin rpy="0 0 0" xyz="0 0 0"/>
      <geometry>
        <mesh filename="package://robbie/meshes/ax12_box2.stl" scale="0.001 0.001 0.001"/>
      </geometry>
      <material name="ax12_color">
        <color rgba="0.1 0.1 0.1 1.0"/>
      </material>
    </visual>
    <collision>
      <origin rpy="0 0 0" xyz="0 0 0"/>
      <geometry>
        <!--<box size="0.032 0.038 0.05" />-->
        <mesh filename="package://robbie/meshes/ax12_box2.stl" scale="0.001 0.001 0.001"/>
      </geometry>
    </collision>
    <inertial>
      <mass value="0.055"/>
      <inertia ixx="0.001" ixy="0.0" ixz="0.0" iyy="0.001" iyz="0.0" izz="0.001"/>
    </inertial>
  </link>
  <gazebo reference="left_wrist_pan_servo">
    <material>Gazebo/FlatBlack</material>
    <selfCollide>false</selfCollide>
    <turnGravityOff>true</turnGravityOff>
  </gazebo>
  <link name="left_wrist_pan_servo_bracket_f3">
    <visual>
      <origin rpy="1.57 0 0" xyz="0 0.005 0"/>
      <geometry>
        <mesh filename="package://robbie/meshes/F3.stl" scale="0.001 0.001 0.001"/>
      </geometry>
      <material name="grey1">
        <color rgba="0.75 0.75 0.75 1.0"/>
      </material>
      <material name="bracket_color">
        <color rgba="0.9 0.9 0.9 1.0"/>
      </material>
    </visual>
    <collision>
      <origin rpy="1.57 0 0" xyz="0 0.005 0"/>
      <geometry>
        <mesh filename="package://robbie/meshes/F3.stl" scale="0.001 0.001 0.001"/>
      </geometry>
    </collision>
    <inertial>
      <mass value="0.01"/>
      <inertia ixx="0.001" ixy="0.0" ixz="0.0" iyy="0.001" iyz="0.0" izz="0.001"/>
    </inertial>
  </link>
  <gazebo reference="left_wrist_pan_servo_bracket_f3">
    <material>Gazebo/WhiteEmissive</material>
    <selfCollide>false</selfCollide>
    <turnGravityOff>true</turnGravityOff>
  </gazebo>
  <!-- <xacro:F3_bracket name="left_wrist_pan_servo_bracket2_f3" xyz="0 0 0" rpy="0 -1.57 0" />-->
  <!-- left_wrist_yaw joint-->
  <link name="left_wrist_yaw_servo">
    <visual>
      <origin rpy="-1.57 0 0" xyz="-0.04 0.05 0"/>
      <geometry>
        <mesh filename="package://robbie/meshes/ax12_box2.stl" scale="0.001 0.001 0.001"/>
      </geometry>
      <material name="ax12_color">
        <color rgba="0.1 0.1 0.1 1.0"/>
      </material>
    </visual>
    <collision>
      <origin rpy="-1.57 0 0" xyz="-0.04 0.05 0"/>
      <geometry>
        <!--<box size="0.032 0.038 0.05" />-->
        <mesh filename="package://robbie/meshes/ax12_box2.stl" scale="0.001 0.001 0.001"/>
      </geometry>
    </collision>
    <inertial>
      <mass value="0.055"/>
      <inertia ixx="0.001" ixy="0.0" ixz="0.0" iyy="0.001" iyz="0.0" izz="0.001"/>
    </inertial>
  </link>
  <gazebo reference="left_wrist_yaw_servo">
    <material>Gazebo/FlatBlack</material>
    <selfCollide>false</selfCollide>
    <turnGravityOff>true</turnGravityOff>
  </gazebo>
  <link name="left_wrist_yaw_bracket_f2">
    <visual>
      <origin rpy="-1.57 0 0" xyz="0 0 0"/>
      <geometry>
        <mesh filename="package://robbie/meshes/F2.stl" scale="0.001 0.001 0.001"/>
      </geometry>
      <material name="bracket_color">
        <color rgba="0.9 0.9 0.9 1.0"/>
      </material>
    </visual>
    <collision>
      <origin rpy="-1.57 0 0" xyz="0 0 0"/>
      <geometry>
        <mesh filename="package://robbie/meshes/F2.stl" scale="0.001 0.001 0.001"/>
      </geometry>
    </collision>
    <inertial>
      <mass value="0.02"/>
      <inertia ixx="0.001" ixy="0.0" ixz="0.0" iyy="0.001" iyz="0.0" izz="0.001"/>
    </inertial>
  </link>
  <gazebo reference="left_wrist_yaw_bracket_f2">
    <material>Gazebo/WhiteEmissive</material>
    <selfCollide>false</selfCollide>
    <turnGravityOff>true</turnGravityOff>
  </gazebo>
  <!-- left_wrist_tilt joint-->
  <link name="left_wrist_tilt_servo">
    <visual>
      <origin rpy="1.57 1.57 0" xyz="0 0 0"/>
      <geometry>
        <mesh filename="package://robbie/meshes/ax12_box2.stl" scale="0.001 0.001 0.001"/>
      </geometry>
      <material name="ax12_color">
        <color rgba="0.1 0.1 0.1 1.0"/>
      </material>
    </visual>
    <collision>
      <origin rpy="1.57 1.57 0" xyz="0 0 0"/>
      <geometry>
        <!--<box size="0.032 0.038 0.05" />-->
        <mesh filename="package://robbie/meshes/ax12_box2.stl" scale="0.001 0.001 0.001"/>
      </geometry>
    </collision>
    <inertial>
      <mass value="0.055"/>
      <inertia ixx="0.001" ixy="0.0" ixz="0.0" iyy="0.001" iyz="0.0" izz="0.001"/>
    </inertial>
  </link>
  <gazebo reference="left_wrist_tilt_servo">
    <material>Gazebo/FlatBlack</material>
    <selfCollide>false</selfCollide>
    <turnGravityOff>true</turnGravityOff>
  </gazebo>
  <link name="left_wrist_tilt_bracket_f2">
    <visual>
      <origin rpy="1.57 1.57 0" xyz="0 0 0"/>
      <geometry>
        <mesh filename="package://robbie/meshes/F2.stl" scale="0.001 0.001 0.001"/>
      </geometry>
      <material name="bracket_color">
        <color rgba="0.9 0.9 0.9 1.0"/>
      </material>
    </visual>
    <collision>
      <origin rpy="1.57 1.57 0" xyz="0 0 0"/>
      <geometry>
        <mesh filename="package://robbie/meshes/F2.stl" scale="0.001 0.001 0.001"/>
      </geometry>
    </collision>
    <inertial>
      <mass value="0.02"/>
      <inertia ixx="0.001" ixy="0.0" ixz="0.0" iyy="0.001" iyz="0.0" izz="0.001"/>
    </inertial>
  </link>
  <gazebo reference="left_wrist_tilt_bracket_f2">
    <material>Gazebo/WhiteEmissive</material>
    <selfCollide>false</selfCollide>
    <turnGravityOff>true</turnGravityOff>
  </gazebo>
  <link name="left_gripper_bracket_f3">
    <visual>
      <origin rpy="1.57 1.57 0" xyz="0 0 0"/>
      <geometry>
        <mesh filename="package://robbie/meshes/F3.stl" scale="0.001 0.001 0.001"/>
      </geometry>
      <material name="grey1">
        <color rgba="0.75 0.75 0.75 1.0"/>
      </material>
      <material name="bracket_color">
        <color rgba="0.9 0.9 0.9 1.0"/>
      </material>
    </visual>
    <collision>
      <origin rpy="1.57 1.57 0" xyz="0 0 0"/>
      <geometry>
        <mesh filename="package://robbie/meshes/F3.stl" scale="0.001 0.001 0.001"/>
      </geometry>
    </collision>
    <inertial>
      <mass value="0.01"/>
      <inertia ixx="0.001" ixy="0.0" ixz="0.0" iyy="0.001" iyz="0.0" izz="0.001"/>
    </inertial>
  </link>
  <gazebo reference="left_gripper_bracket_f3">
    <material>Gazebo/WhiteEmissive</material>
    <selfCollide>false</selfCollide>
    <turnGravityOff>true</turnGravityOff>
  </gazebo>
  <!-- left_Gripper_joint-->
  <link name="left_gripper_servo">
    <visual>
      <origin rpy="0 0 -1.57" xyz="0 0 0"/>
      <geometry>
        <mesh filename="package://robbie/meshes/ax12_box2.stl" scale="0.001 0.001 0.001"/>
      </geometry>
      <material name="ax12_color">
        <color rgba="0.1 0.1 0.1 1.0"/>
      </material>
    </visual>
    <collision>
      <origin rpy="0 0 -1.57" xyz="0 0 0"/>
      <geometry>
        <!--<box size="0.032 0.038 0.05" />-->
        <mesh filename="package://robbie/meshes/ax12_box2.stl" scale="0.001 0.001 0.001"/>
      </geometry>
    </collision>
    <inertial>
      <mass value="0.055"/>
      <inertia ixx="0.001" ixy="0.0" ixz="0.0" iyy="0.001" iyz="0.0" izz="0.001"/>
    </inertial>
  </link>
  <gazebo reference="left_gripper_servo">
    <material>Gazebo/FlatBlack</material>
    <selfCollide>false</selfCollide>
    <turnGravityOff>true</turnGravityOff>
  </gazebo>
  <link name="left_gripper_bracket_f2">
    <visual>
      <origin rpy="0 0 1.57" xyz="0 0 0"/>
      <geometry>
        <mesh filename="package://robbie/meshes/F2.stl" scale="0.001 0.001 0.001"/>
      </geometry>
      <material name="bracket_color">
        <color rgba="0.9 0.9 0.9 1.0"/>
      </material>
    </visual>
    <collision>
      <origin rpy="0 0 1.57" xyz="0 0 0"/>
      <geometry>
        <mesh filename="package://robbie/meshes/F2.stl" scale="0.001 0.001 0.001"/>
      </geometry>
    </collision>
    <inertial>
      <mass value="0.02"/>
      <inertia ixx="0.001" ixy="0.0" ixz="0.0" iyy="0.001" iyz="0.0" izz="0.001"/>
    </inertial>
  </link>
  <gazebo reference="left_gripper_bracket_f2">
    <material>Gazebo/WhiteEmissive</material>
    <selfCollide>false</selfCollide>
    <turnGravityOff>true</turnGravityOff>
  </gazebo>
  <link name="left_right_finger_link">
    <visual>
      <origin rpy="1.57 0 1.57" xyz="0 0 0"/>
      <geometry>
        <box size="-0.08 0.005 0.035"/>
      </geometry>
      <material name="blue1">
        <color rgba="0 0 0.9 1.0"/>
      </material>
    </visual>
    <collision>
      <origin rpy="1.57 0 1.57" xyz="0 0 0"/>
      <geometry>
        <box size="-0.08 0.005 0.035"/>
      </geometry>
    </collision>
  </link>
  <gazebo reference="left_right_finger_link">
    <material>Gazebo/FlatBlack</material>
    <selfCollide>false</selfCollide>
    <turnGravityOff>true</turnGravityOff>
  </gazebo>
  <link name="left_left_finger_link">
    <visual>
      <origin rpy="1.57 0 1.57" xyz="0 0 0"/>
      <geometry>
        <box size="0.08 0.005 0.035"/>
      </geometry>
      <material name="grey3">
        <color rgba="0.8 0.8 0.8 1.0"/>
      </material>
    </visual>
    <collision>
      <origin rpy="1.57 0 1.57" xyz="0 0 0"/>
      <geometry>
        <box size="0.08 0.005 0.035"/>
      </geometry>
    </collision>
  </link>
  <gazebo reference="left_left_finger_link">
    <material>Gazebo/FlatBlack</material>
    <selfCollide>false</selfCollide>
    <turnGravityOff>true</turnGravityOff>
  </gazebo>
  <!-- head details-->
  <link name="head_tilt_bracket">
    <visual>
      <origin rpy="0 3.1415 0" xyz="0 0 0"/>
      <geometry>
        <mesh filename="package://robbie/meshes/F2.stl" scale="0.001 0.001 0.001"/>
      </geometry>
      <material name="bracket_color">
        <color rgba="0.9 0.9 0.9 1.0"/>
      </material>
    </visual>
    <collision>
      <origin rpy="0 3.1415 0" xyz="0 0 0"/>
      <geometry>
        <mesh filename="package://robbie/meshes/F2.stl" scale="0.001 0.001 0.001"/>
      </geometry>
    </collision>
    <inertial>
      <mass value="0.02"/>
      <inertia ixx="0.001" ixy="0.0" ixz="0.0" iyy="0.001" iyz="0.0" izz="0.001"/>
    </inertial>
  </link>
  <gazebo reference="head_tilt_bracket">
    <material>Gazebo/WhiteEmissive</material>
    <selfCollide>false</selfCollide>
    <turnGravityOff>true</turnGravityOff>
  </gazebo>
  <link name="head_tilt_link">
    <visual>
      <origin rpy="3.1415 0 0" xyz="0 0 0"/>
      <geometry>
        <mesh filename="package://robbie/meshes/ax12_box2.stl" scale="0.001 0.001 0.001"/>
      </geometry>
      <material name="ax12_color">
        <color rgba="0.1 0.1 0.1 1.0"/>
      </material>
    </visual>
    <collision>
      <origin rpy="3.1415 0 0" xyz="0 0 0"/>
      <geometry>
        <!--<box size="0.032 0.038 0.05" />-->
        <mesh filename="package://robbie/meshes/ax12_box2.stl" scale="0.001 0.001 0.001"/>
      </geometry>
    </collision>
    <inertial>
      <mass value="0.055"/>
      <inertia ixx="0.001" ixy="0.0" ixz="0.0" iyy="0.001" iyz="0.0" izz="0.001"/>
    </inertial>
  </link>
  <gazebo reference="head_tilt_link">
    <material>Gazebo/FlatBlack</material>
    <selfCollide>false</selfCollide>
    <turnGravityOff>true</turnGravityOff>
  </gazebo>
  <link name="head_pan_bracket">
    <visual>
      <origin rpy="0 0 0" xyz="0 0 0"/>
      <geometry>
        <mesh filename="package://robbie/meshes/F3.stl" scale="0.001 0.001 0.001"/>
      </geometry>
      <material name="grey1">
        <color rgba="0.75 0.75 0.75 1.0"/>
      </material>
      <material name="bracket_color">
        <color rgba="0.9 0.9 0.9 1.0"/>
      </material>
    </visual>
    <collision>
      <origin rpy="0 0 0" xyz="0 0 0"/>
      <geometry>
        <mesh filename="package://robbie/meshes/F3.stl" scale="0.001 0.001 0.001"/>
      </geometry>
    </collision>
    <inertial>
      <mass value="0.01"/>
      <inertia ixx="0.001" ixy="0.0" ixz="0.0" iyy="0.001" iyz="0.0" izz="0.001"/>
    </inertial>
  </link>
  <gazebo reference="head_pan_bracket">
    <material>Gazebo/WhiteEmissive</material>
    <selfCollide>false</selfCollide>
    <turnGravityOff>true</turnGravityOff>
  </gazebo>
  <link name="head_pan_link">
    <visual>
      <origin rpy=" 1.57 0 1.57" xyz="0 0 0"/>
      <geometry>
        <mesh filename="package://robbie/meshes/ax12_box2.stl" scale="0.001 0.001 0.001"/>
      </geometry>
      <material name="ax12_color">
        <color rgba="0.1 0.1 0.1 1.0"/>
      </material>
    </visual>
    <collision>
      <origin rpy=" 1.57 0 1.57" xyz="0 0 0"/>
      <geometry>
        <!--<box size="0.032 0.038 0.05" />-->
        <mesh filename="package://robbie/meshes/ax12_box2.stl" scale="0.001 0.001 0.001"/>
      </geometry>
    </collision>
    <inertial>
      <mass value="0.055"/>
      <inertia ixx="0.001" ixy="0.0" ixz="0.0" iyy="0.001" iyz="0.0" izz="0.001"/>
    </inertial>
  </link>
  <gazebo reference="head_pan_link">
    <material>Gazebo/FlatBlack</material>
    <selfCollide>false</selfCollide>
    <turnGravityOff>true</turnGravityOff>
  </gazebo>
  <link name="neck_link">
    <visual>
      <origin rpy="1.57 0 -1.570" xyz="0 0 0"/>
      <geometry>
        <mesh filename="package://robbie/meshes/F3.stl" scale="0.001 0.001 0.001"/>
      </geometry>
      <material name="grey1">
        <color rgba="0.75 0.75 0.75 1.0"/>
      </material>
      <material name="bracket_color">
        <color rgba="0.9 0.9 0.9 1.0"/>
      </material>
    </visual>
    <collision>
      <origin rpy="1.57 0 -1.570" xyz="0 0 0"/>
      <geometry>
        <mesh filename="package://robbie/meshes/F3.stl" scale="0.001 0.001 0.001"/>
      </geometry>
    </collision>
    <inertial>
      <mass value="0.01"/>
      <inertia ixx="0.001" ixy="0.0" ixz="0.0" iyy="0.001" iyz="0.0" izz="0.001"/>
    </inertial>
  </link>
  <gazebo reference="neck_link">
    <material>Gazebo/WhiteEmissive</material>
    <selfCollide>false</selfCollide>
    <turnGravityOff>true</turnGravityOff>
  </gazebo>
  <link name="head_base_link">
    <visual>
      <origin rpy="0 0 0" xyz="0 0 0"/>
      <geometry>
        <box size="0.06 0.08 0.005"/>
      </geometry>
      <material name="black">
        <color rgba="0.1 0.1 0.1 1.0"/>
      </material>
    </visual>
    <collision>
      <origin rpy="0 0 0" xyz="0 0 0"/>
      <geometry>
        <box size="0.06 0.08 0.005"/>
      </geometry>
    </collision>
  </link>
  <gazebo reference="head_base_link">
    <material>Gazebo/FlatBlack</material>
    <selfCollide>false</selfCollide>
    <turnGravityOff>true</turnGravityOff>
  </gazebo>
  <link name="head_link">
    <visual>
      <geometry>
        <mesh filename="package://robbie_description/meshes/head.stl" scale="0.001 0.001 0.001"/>
      </geometry>
      <material name="gold">
        <color rgba="0.5 0.3 0 1.0"/>
      </material>
      <origin rpy="1.57 0 1.57" xyz="0 0 0"/>
    </visual>
  </link>
  <link name="head_link_fake">
    <inertial>
      <mass value="0.0001"/>
      <origin xyz="0 0 0"/>
      <inertia ixx="0.0001" ixy="0.0" ixz="0.0" iyy="0.0001" iyz="0.0" izz="0.0001"/>
    </inertial>
  </link>
  <link name="kinect_link">
    <inertial>
      <mass value="1.0"/>
      <origin xyz="0 0 0"/>
      <inertia ixx="1.0" ixy="0.0" ixz="0.0" iyy="1.0" iyz="0.0" izz="1.0"/>
    </inertial>
    <visual>
      <origin rpy="0 0 0" xyz=" 0 0 0 "/>
      <geometry>
        <mesh filename="package://robbie_description/meshes/kinect.stl" scale="0.001 0.001 0.001"/>
      </geometry>
      <material name="ax12_color">
        <color rgba="0.1 0.1 0.1 1.0"/>
      </material>
    </visual>
    <collision>
      <origin rpy="0 0 0" xyz="0 0 0"/>
      <geometry>
        <mesh filename="package://robbie_description/meshes/kinect.stl" scale="0.001 0.001 0.001"/>
      </geometry>
    </collision>
  </link>
  <link name="camera_link">
    <visual>
      <origin rpy="0 1.57 0" xyz="0 0 0"/>
      <geometry>
        <cylinder length="0.035" radius="0.01"/>
      </geometry>
      <material name="grey1">
        <color rgba="0.75 0.75 0.75 1.0"/>
      </material>
    </visual>
    <collision>
      <origin rpy="0 1.57 0" xyz="0 0 0"/>
      <geometry>
        <cylinder length="0.035" radius="0.01"/>
      </geometry>
    </collision>
    <inertial>
      <mass value="0.1"/>
      <inertia ixx="0.001" ixy="0.0" ixz="0.0" iyy="0.001" iyz="0.0" izz="0.001"/>
    </inertial>
  </link>
  <gazebo reference="camera_link">
    <material>Gazebo/Grey</material>
    <selfCollide>false</selfCollide>
    <turnGravityOff>true</turnGravityOff>
  </gazebo>
  <!-- virtal joints-->
  <link name="right_gripper_link">
    <visual>
      <origin rpy="0 0 0" xyz="0.05 0 0"/>
      <geometry>
        <box size="0.001 0.001 0.001"/>
      </geometry>
    </visual>
    <collision>
      <origin rpy="0 0 0" xyz="0.05 0 0"/>
      <geometry>
        <box size="0.001 0.001 0.001"/>
      </geometry>
    </collision>
  </link>
  <link name="left_gripper_link">
    <visual>
      <origin rpy="0 0 0" xyz="-0.05 0 0"/>
      <geometry>
        <box size="0.001 0.001 0.001"/>
      </geometry>
    </visual>
    <collision>
      <origin rpy="0 0 0" xyz="-0.05 0 0"/>
      <geometry>
        <box size="0.001 0.001 0.001"/>
      </geometry>
    </collision>
  </link>
  <!-- ##############################   joints ##################333333-->
  <joint name="base_footprint_joint" type="fixed">
    <parent link="base_footprint"/>
    <child link="base_link"/>
    <origin rpy="0 0 0" xyz="-0.1 0 0"/>
  </joint>
  <joint name="base_link_joint" type="fixed">
    <parent link="base_link"/>
    <child link="deck_link"/>
    <origin rpy="0 0 0" xyz="-0.1 0 .36"/>
  </joint>
  <joint name="left_wheel_joint" type="fixed">
    <parent link="base_link"/>
    <child link="left_wheel"/>
    <origin rpy="0 0 0" xyz="0.1 -0.2 0.1"/>
  </joint>
  <joint name="right_wheel_joint" type="fixed">
    <parent link="base_link"/>
    <child link="right_wheel"/>
    <origin rpy="0 0 0" xyz="0.1 0.2 0.1"/>
  </joint>
  <joint name="castor_wheel_joint_l" type="fixed">
    <parent link="base_link"/>
    <child link="castor_wheel_l"/>
    <origin rpy="0 0 0" xyz="-0.20 -0.13 0.05"/>
  </joint>
  <joint name="castor_wheel_joint_r" type="fixed">
    <parent link="base_link"/>
    <child link="castor_wheel_r"/>
    <origin rpy="0 0 0" xyz="-0.20 0.13 0.05"/>
  </joint>
  <!--#################  Upper torso#############################-->
  <joint name="pan_joint" type="revolute">
    <parent link="deck_link"/>
    <child link="pan_link"/>
    <origin rpy="0 0 0" xyz="0.1 0 0.275"/>
    <axis xyz="0 0 1"/>
    <limit effort="10" lower="-1" upper="1" velocity="0"/>
  </joint>
  <joint name="torso_link" type="fixed">
    <parent link="pan_link"/>
    <child link="upper_torso"/>
    <origin rpy="0 0 0" xyz="0.05 0 0.26"/>
  </joint>
  <joint name="chest_link" type="fixed">
    <parent link="upper_torso"/>
    <child link="upper_chest"/>
    <origin rpy="0 0 0" xyz="0.02 0 0.03"/>
  </joint>
  <joint name="right_arm_tilt_joint" type="revolute">
    <parent link="upper_torso"/>
    <child link="right_shoulder_tilt"/>
    <origin rpy="0 0 0" xyz="-0.045 -0.145 0.105"/>
    <axis xyz="1 0 0"/>
    <limit effort="10" lower="-1.34" upper="0.1" velocity="0"/>
  </joint>
  <joint name="right_arm_lift_joint" type="revolute">
    <parent link="right_shoulder_tilt"/>
    <child link="right_shoulder_lift"/>
    <origin rpy="0 -1.57 0" xyz="-0.0 -0.077 -0.04"/>
    <axis xyz="0 1 0"/>
    <limit effort="10" lower="-1.57" upper="1.57" velocity="0"/>
  </joint>
  <joint name="right_arm_rotate_joint" type="revolute">
    <parent link="right_shoulder_lift"/>
    <child link="right_shoulder_rotate"/>
    <origin rpy="0 0 0" xyz="0 0 -0.065"/>
    <axis xyz="0 0 -1"/>
    <limit effort="10" lower="-3.14" upper="0.2" velocity="0"/>
  </joint>
  <joint name="right_elbow_link" type="fixed">
    <parent link="right_shoulder_rotate"/>
    <child link="right_elbow_link"/>
    <origin rpy="0 0 0" xyz="0.01 0 -0.17"/>
  </joint>
  <joint name="right_arm_elbow_joint" type="revolute">
    <parent link="right_elbow_link"/>
    <child link="right_elbow"/>
    <origin rpy="0 -1.57 0" xyz="0.01 0.01 0.0"/>
    <axis xyz="0 1 0"/>
    <limit effort="10" lower="-2.20" upper="0.1" velocity="0"/>
  </joint>
  <joint name="right_arm_forearm_link" type="fixed">
    <parent link="right_elbow"/>
    <child link="right_forearm_link"/>
    <origin rpy="1.57 0 0" xyz="-0.08 -0.0 -0.0"/>
  </joint>
  <!--right_arm_wrist_pan_joint-->
  <joint name="right_arm_wrist_pan_bracket" type="fixed">
    <parent link="right_forearm_link"/>
    <child link="wrist_pan_servo"/>
    <origin rpy="0 0 1.57" xyz="-0.21 0.0 0.0"/>
  </joint>
  <joint name="right_arm_wrist_pan_joint" type="revolute">
    <parent link="wrist_pan_servo"/>
    <child link="wrist_pan_servo_bracket_f3"/>
    <origin rpy="0 1.57 0" xyz="0. 0.015 0.0"/>
    <axis xyz="0 1 0"/>
    <limit effort="10" lower="-2.61" upper="2.61" velocity="0"/>
    <dynamics damping="0.0"/>
  </joint>
  <joint name="right_arm_wrist_tilt_bracket" type="fixed">
    <parent link="wrist_pan_servo_bracket_f3"/>
    <child link="wrist_tilt_servo"/>
    <origin rpy="0 0 0" xyz="0.04 0 0.0"/>
    <axis xyz="1 0 0"/>
  </joint>
  <!--wrist_tilt_joint-->
  <joint name="right_arm_wrist_yaw_joint" type="revolute">
    <parent link="wrist_tilt_servo"/>
    <child link="wrist_tilt_bracket_f2"/>
    <origin rpy="-1.57 0 1.57" xyz="-0.04 0.05 0"/>
    <axis xyz="0 1 0"/>
    <limit effort="10" lower="-1.57" upper="1.57" velocity="0"/>
    <dynamics damping="0.0"/>
  </joint>
  <joint name="right_arm_gripper_bracket" type="fixed">
    <parent link="wrist_tilt_bracket_f2"/>
    <child link="gripper_bracket_f3"/>
    <origin rpy="1.57 1.57 0" xyz="0.025 0.025 0.0"/>
    <!--now-->
  </joint>
  <joint name="right_arm_gripper_servo" type="fixed">
    <parent link="gripper_bracket_f3"/>
    <child link="gripper_servo"/>
    <origin rpy="-1.57 0 1.57" xyz="0.0 0.02 0.02"/>
  </joint>
  <joint name="right_gripper_joint" type="fixed">
    <origin rpy="-1.570795 0 1.570795" xyz="0 0.06 0.01"/>
    <parent link="gripper_bracket_f3"/>
    <child link="right_gripper_link"/>
  </joint>
  <!-- gripper_joint-->
  <joint name="right_arm_gripper_joint" type="revolute">
    <parent link="gripper_servo"/>
    <child link="gripper_bracket_f2"/>
    <origin rpy="0 1.57 -1.57" xyz="0 0.0 0.0"/>
    <axis xyz="1 0 0"/>
    <limit effort="10" lower="-0.36" upper="0.28" velocity="0"/>
    <dynamics damping="0.0"/>
  </joint>
  <joint name="right_arm_finger_link_l" type="fixed">
    <parent link="gripper_servo"/>
    <child link="left_finger_link"/>
    <origin rpy="0 1.57 -1.57" xyz="0.03 0.04 0.0"/>
  </joint>
  <!-- moving finger   ############-->
  <joint name="right_arm_finger_link_r" type="fixed">
    <parent link="gripper_bracket_f2"/>
    <child link="right_finger_link"/>
    <origin rpy="0 0 0" xyz="0 0.03 0.03"/>
  </joint>
  <!--##########################        left arm             #############################-->
  <joint name="left_arm_tilt_joint" type="revolute">
    <parent link="upper_torso"/>
    <child link="left_shoulder_tilt"/>
    <origin rpy="0 0 0" xyz="-0.045 0.145 0.105"/>
    <axis xyz="-1 0 0"/>
    <limit effort="10" lower="-1.34" upper="0.1" velocity="0"/>
  </joint>
  <joint name="left_arm_lift_joint" type="revolute">
    <parent link="left_shoulder_tilt"/>
    <child link="left_shoulder_lift"/>
    <origin rpy="0 -1.57 0" xyz="0 0.02 -0.04"/>
    <axis xyz="0 1 0"/>
    <limit effort="10" lower="-1.57" upper="1.57" velocity="0"/>
  </joint>
  <joint name="left_arm_rotate_joint" type="revolute">
    <parent link="left_shoulder_lift"/>
    <child link="left_shoulder_rotate"/>
    <origin rpy="0 0 0" xyz="0 0.06 -0.055"/>
    <axis xyz="0 0 -1"/>
    <limit effort="10" lower="0.2" upper="3.14" velocity="0"/>
  </joint>
  <joint name="left_elbow_link" type="fixed">
    <parent link="left_shoulder_rotate"/>
    <child link="left_elbow_link"/>
    <origin rpy="0 0 0" xyz="0.01 0 -0.17"/>
  </joint>
  <joint name="left_arm_elbow_joint" type="revolute">
    <parent link="left_elbow_link"/>
    <child link="left_elbow"/>
    <origin rpy="0 -1.57 0" xyz="0.01 0.01 0.0"/>
    <axis xyz="0 1 0"/>
    <limit effort="10" lower="-2.20" upper="0.17" velocity="0"/>
  </joint>
  <joint name="left_arm_forearm_link" type="fixed">
    <parent link="left_elbow"/>
    <child link="left_forearm_link"/>
    <origin rpy="1.57 0 0" xyz="-0.08 -0.0 -0.0"/>
  </joint>
  <!--left_arm_wrist_pan_joint-->
  <joint name="left_arm_wrist_pan_bracket" type="fixed">
    <parent link="left_forearm_link"/>
    <child link="left_wrist_pan_servo"/>
    <origin rpy="0 0 1.57" xyz="-0.21 0.0 0.0"/>
    <!--now-->
  </joint>
  <joint name="left_arm_wrist_pan_joint" type="revolute">
    <!--revolute-->
    <parent link="left_wrist_pan_servo"/>
    <child link="left_wrist_pan_servo_bracket_f3"/>
    <origin rpy="0 0 0" xyz="0. 0.015 0.0"/>
    <axis xyz="0 1 0"/>
    <limit effort="10" lower="-2.61" upper="2.61" velocity="0"/>
    <dynamics damping="0.0"/>
  </joint>
  <joint name="left_arm_wrist_tilt_bracket" type="fixed">
    <parent link="left_wrist_pan_servo_bracket_f3"/>
    <child link="left_wrist_yaw_servo"/>
    <origin rpy="0 0 0" xyz="0.04 0 0.0"/>
    <axis xyz="1 0 0"/>
  </joint>
  <!--wrist_yaw_joint-->
  <joint name="left_arm_wrist_yaw_joint" type="revolute">
    <!--revolute-->
    <parent link="left_wrist_yaw_servo"/>
    <child link="left_wrist_yaw_bracket_f2"/>
    <origin rpy="0 0 0" xyz="-0.04 0.05 0"/>
    <axis xyz="0 0 -1"/>
    <limit effort="10" lower="-1.57" upper="1.57" velocity="0"/>
    <dynamics damping="0.0"/>
  </joint>
  <joint name="left_arm_wrist_yaw_bracket" type="fixed">
    <parent link="left_wrist_yaw_bracket_f2"/>
    <child link="left_wrist_tilt_bracket_f2"/>
    <origin rpy="0 0 0" xyz="-0.0 0.052 0.0"/>
    <axis xyz="1 0 0"/>
    <limit effort="10" lower="-1.57" upper="1.57" velocity="0"/>
    <dynamics damping="0.0"/>
  </joint>
  <!--wrist_tilt_joint-->
  <joint name="left_arm_wrist_tilt_joint" type="revolute">
    <!--revolute-->
    <parent link="left_wrist_tilt_bracket_f2"/>
    <child link="left_wrist_tilt_servo"/>
    <origin rpy="0 0 0" xyz="-0 -0.0 0"/>
    <axis xyz="1 0 0"/>
    <limit effort="10" lower="-1.57" upper="1.57" velocity="0"/>
    <dynamics damping="0.0"/>
  </joint>
  <joint name="left_arm_gripper_bracket" type="fixed">
    <parent link="left_wrist_tilt_servo"/>
    <child link="left_gripper_bracket_f3"/>
    <origin rpy="0 1.57 0" xyz="0.0 0.035 0.0"/>
  </joint>
  <joint name="left_arm_gripper_servo" type="fixed">
    <parent link="left_gripper_bracket_f3"/>
    <child link="left_gripper_servo"/>
    <origin rpy="0 3.14 0" xyz="0.0 0.02 -0.02"/>
  </joint>
  <joint name="left_gripper_joint" type="fixed">
    <origin rpy="1.570795 0 1.570795" xyz="0 0.06 -0.01"/>
    <parent link="left_gripper_bracket_f3"/>
    <child link="left_gripper_link"/>
  </joint>
  <!-- left gripper_joint-->
  <joint name="left_arm_gripper_joint" type="revolute">
    <!--revolute-->
    <parent link="left_gripper_servo"/>
    <child link="left_gripper_bracket_f2"/>
    <origin rpy="0 0 0" xyz="0 0.0 0.0"/>
    <axis xyz="1 0 0"/>
    <limit effort="10" lower="-1.0" upper="0.3" velocity="0"/>
    <dynamics damping="0.0"/>
  </joint>
  <joint name="left_arm_finger_link_l" type="fixed">
    <parent link="left_gripper_servo"/>
    <child link="left_left_finger_link"/>
    <origin rpy="0 0 0" xyz="0. 0.03 -0.04"/>
  </joint>
  <joint name="left_arm_finger_link_r" type="fixed">
    <parent link="left_gripper_bracket_f2"/>
    <child link="left_right_finger_link"/>
    <origin rpy="0 0 0" xyz="0 0.03 0.03"/>
  </joint>
  <!-- #####################################Head joints#########################################-->
  <joint name="head_tilt_servo" type="fixed">
    <parent link="upper_torso"/>
    <child link="head_tilt_bracket"/>
    <origin rpy="0 0 0" xyz="-0.05 0. 0.15"/>
  </joint>
  <!-- Head tilt joint-->
  <joint name="head_tilt_mod_joint" type="revolute">
    <parent link="head_tilt_bracket"/>
    <child link="head_tilt_link"/>
    <origin rpy="0 0 0" xyz="0 0 0.0"/>
    <axis xyz="0 1 0"/>
    <limit effort="10" lower="-2.6" upper="2.6" velocity="0"/>
    <dynamics damping="0.0"/>
  </joint>
  <!-- Head tilt joint fake-->
  <joint name="head_tilt_joint" type="fixed">
    <parent link="head_tilt_bracket"/>
    <child link="head_link_fake"/>
    <origin rpy="0 0 0" xyz="0 0 0.0"/>
    <axis xyz="0 1 0"/>
    <limit effort="10" lower="-2.6" upper="2.6" velocity="0"/>
    <dynamics damping="0.0"/>
  </joint>
  <joint name="head_pan_servo" type="fixed">
    <parent link="head_tilt_link"/>
    <child link="head_pan_bracket"/>
    <origin rpy="0 0 0" xyz="-0.0 0 0.04"/>
  </joint>
  <!-- head_pan_joint-->
  <joint name="head_pan_joint" type="revolute">
    <parent link="head_pan_bracket"/>
    <child link="head_pan_link"/>
    <origin rpy="0 0 0" xyz="0.0 0 0.02"/>
    <origin rpy="0 0 0" xyz="0 0 0.0"/>
    <axis xyz="0 0 1"/>
    <limit effort="10" lower="-2" upper="2" velocity="0"/>
    <dynamics damping="0.0"/>
  </joint>
  <joint name="head_neck_link" type="fixed">
    <parent link="head_pan_link"/>
    <child link="neck_link"/>
    <origin rpy="0 0 0" xyz="-0.04 0 0.0"/>
  </joint>
  <joint name="neck_joint" type="fixed">
    <parent link="neck_link"/>
    <child link="head_base_link"/>
    <origin rpy="0 0 0" xyz="0.02 0 0.0"/>
  </joint>
  <joint name="head_joint" type="fixed">
    <parent link="head_base_link"/>
    <child link="head_link"/>
    <origin rpy="0 0 0" xyz="-0.02 -0.097 -0.45"/>
  </joint>
  <joint name="camera_link" type="fixed">
    <parent link="head_link"/>
    <child link="camera_link"/>
    <origin rpy="0 0 0" xyz="0.13 0.1 0.6"/>
  </joint>
  <joint name="kinect_joint" type="fixed">
    <parent link="base_link"/>
    <child link="kinect_link"/>
    <origin rpy="0 0 0" xyz="0.2 0 0.26"/>
  </joint>
  <joint name="kinect_depth_joint" type="fixed">
    <origin rpy="0 0 0" xyz="0 0.018 0"/>
    <parent link="kinect_link"/>
    <child link="kinect_depth_frame"/>
  </joint>
  <link name="kinect_depth_frame">
    <inertial>
      <mass value="0.0001"/>
      <origin xyz="0 0 0"/>
      <inertia ixx="0.0001" ixy="0.0" ixz="0.0" iyy="0.0001" iyz="0.0" izz="0.0001"/>
    </inertial>
  </link>
  <joint name="kinect_depth_optical_joint" type="fixed">
    <origin rpy="-1.570795 0 -1.570795" xyz="0 0 0"/>
    <parent link="kinect_link"/>
    <child link="kinect_depth_optical_frame"/>
  </joint>
  <link name="kinect_depth_optical_frame">
    <inertial>
      <mass value="0.0001"/>
      <origin xyz="0 0 0"/>
      <inertia ixx="0.0001" ixy="0.0" ixz="0.0" iyy="0.0001" iyz="0.0" izz="0.0001"/>
    </inertial>
  </link>
  <joint name="kinect_rgb_optical_joint" type="fixed">
    <origin rpy="-1.570795 0 -1.570795" xyz="0 0 0"/>
    <parent link="kinect_depth_optical_frame"/>
    <child link="kinect_rgb_optical_frame"/>
  </joint>
  <link name="kinect_rgb_optical_frame">
    <inertial>
      <mass value="0.001"/>
      <origin xyz="0 0 0"/>
      <inertia ixx="0.0001" ixy="0.0" ixz="0.0" iyy="0.0001" iyz="0.0" izz="0.0001"/>
    </inertial>
  </link>
  <gazebo reference="robbie">
  	</gazebo>
</robot>

